Workbook
Name Category_List: Lists!$B$2:$B$4
Name Department_List: Lists!$E$2:$E$7
Name Equipment_List: Lists!$A$2:$A$53
Name Shift_List: Lists!$C$2:$C$3
Name Shift_List: Lists!$C$2:$C$3
Name UOM_List: Lists!$D$2:$D$17

Sheet Master Dashboard
B1: INVENTORY & NON INVENTORY DASHBOARD
B2: LOTTE KOLSON PVT LTD
B4: Inventory Stock Value (PKR) | D4: Non Inventory Stock Value (PKR) | F4: Total Stock Value (PKR) | H4: QUICK DECISION BOARD | I4: Current | J4: Signal | K4: Next Action | L4: Owner
B5: =SUM(Inventory!J4:J1002) -> 14080023 | D5: =SUM('Non Inventory'!J4:J997) -> 8997266.4 | F5: =SUM(B5:E5) -> 23077289 | H5: Issuance Gap | I5: =$L$22-$G$22 -> 1672430.4 | J5: =IF(I5>0,"Immediate",IF(I5=0,"Balanced","OK")) -> Immediate | K5: =IF(J5="Immediate","Control outward issuance","Maintain normal flow") -> Control outward issuance | L5: Store / Finance
H6: Top Pressure Category | I6: {=INDEX($B$77:$B$80,MATCH(MAX(ABS($J$77:$J$80)),ABS($J$77:$J$80),0))} -> Inventory | J6: =INDEX($K$77:$K$80,MATCH(I6,$B$77:$B$80,0)) -> High Pressure | K6: =INDEX($L$77:$L$80,MATCH(I6,$B$77:$B$80,0)) -> Review issuance control | L6: Procurement
B7: Total Inward Value (PKR) | D7: Total Issuance Value (PKR) | H7: Machine Focus | I7: =COUNTIF($J$31:$J$38,"Focus") -> 2 | J7: =IF(I7>=2,"Priority",IF(I7=1,"Watch","OK")) -> Priority | K7: =IF(J7="Priority","Review focus machines","Monitor machine trend") -> Review focus machines | L7: Maintenance
B8: =SUM('Daily Inward'!J4:J994) -> 4028137 | D8: =SUM('Daily Issuance'!O4:O998) -> 5700567.4 | H8: Data Readiness | I8: =COUNTIF($L$33:$L$38,"No Data") -> 6 | J8: =IF(I8>=3,"Update Required",IF(I8=0,"Complete","Watch")) -> Update Required | K8: =IF(J8="Update Required","Update future month data","Keep monthly refresh") -> Update future month data | L8: Reporting
B10: MONTH WISE PRICE SUMMARY (MAY 2026 - DEC 2026)
B11: Inward & Issuance Price Value by Inventory / Non Inventory
B12: INWARD PRICE VALUE (PKR) | H12: ISSUANCE PRICE VALUE (PKR)
B13: Month | C13: Inventory Inward | D13: Non Inventory Inward | E13: Services | F13: PattyCash | G13: Total Inward | H13: Inventory Issuance | I13: Non Inventory Issuance | J13: Services | K13: Patty Cash | L13: Total Issuance
B14: May 2026 | C14: =SUMIFS('Daily Inward'!$J$4:$J$991,'Daily Inward'!$E$4:$E$991,"Inventory",'Daily Inward'!$B$4:$B$991,">="&DATE(2026,5,1),'Daily Inward'!$B$4:$B$991,"<"&EDATE(DATE(2026,5,1),1)) -> 1086500 | D14: =SUMIFS('Daily Inward'!$J$4:$J$1048576,'Daily Inward'!$E$4:$E$1048576,"Non Inventory",'Daily Inward'!$B$4:$B$1048576,">="&DATE(2026,5,1),'Daily Inward'!$B$4:$B$1048576,"<"&EDATE(DATE(2026,5,1),1)) -> 1018303 | E14: =SUMIFS('Daily Inward'!$J:$J,'Daily Inward'!$E:$E,"Services",'Daily Inward'!$B:$B,">="&DATE(2026,5,1),'Daily Inward'!$B:$B,"<"&EDATE(DATE(2026,5,1),1)) -> 785200 | F14: =SUMIFS('Daily Inward'!$J:$J,'Daily Inward'!$E:$E,"Patty Cash",'Daily Inward'!$B:$B,">="&DATE(2026,5,1),'Daily Inward'!$B:$B,"<"&EDATE(DATE(2026,5,1),1)) -> 14496.56 | G14: =SUM(C14:F14) -> 2904499.6 | H14: =SUMIFS('Daily Issuance'!$O:$O,'Daily Issuance'!$E:$E,"Inventory",'Daily Issuance'!$B:$B,">="&DATE(2026,5,1),'Daily Issuance'!$B:$B,"<"&EDATE(DATE(2026,5,1),1)) -> 1717496 | I14: =SUMIFS('Daily Issuance'!$O:$O,'Daily Issuance'!$E:$E,"Non Inventory",'Daily Issuance'!$B:$B,">="&DATE(2026,5,1),'Daily Issuance'!$B:$B,"<"&EDATE(DATE(2026,5,1),1)) -> 352080 | J14: =SUMIFS('Daily Issuance'!$O:$O,'Daily Issuance'!$E:$E,"Services",'Daily Issuance'!$B:$B,">="&DATE(2026,5,1),'Daily Issuance'!$B:$B,"<"&EDATE(DATE(2026,5,1),1)) -> 785200 | K14: =SUMIFS('Daily Issuance'!$O:$O,'Daily Issuance'!$E:$E,"Patty Cash",'Daily Issuance'!$B:$B,">="&DATE(2026,5,1),'Daily Issuance'!$B:$B,"<"&EDATE(DATE(2026,5,1),1)) -> 16108.96 | L14: =SUM(H14:K14) -> 2870885
B15: Jun 2026 | C15: =SUMIFS('Daily Inward'!$J:$J,'Daily Inward'!$E:$E,"Inventory",'Daily Inward'!$B:$B,">="&DATE(2026,6,1),'Daily Inward'!$B:$B,"<"&EDATE(DATE(2026,6,1),1)) -> 0 | D15: =SUMIFS('Daily Inward'!$J:$J,'Daily Inward'!$E:$E,"Non Inventory",'Daily Inward'!$B:$B,">="&DATE(2026,6,1),'Daily Inward'!$B:$B,"<"&EDATE(DATE(2026,6,1),1)) -> 716382.81 | E15: =SUMIFS('Daily Inward'!$J:$J,'Daily Inward'!$E:$E,"Services",'Daily Inward'!$B:$B,">="&DATE(2026,6,1),'Daily Inward'!$B:$B,"<"&EDATE(DATE(2026,6,1),1)) -> 398000 | F15: =SUMIFS('Daily Inward'!$J:$J,'Daily Inward'!$E:$E,"Patty Cash",'Daily Inward'!$B:$B,">="&DATE(2026,6,1),'Daily Inward'!$B:$B,"<"&EDATE(DATE(2026,6,1),1)) -> 9254.6489 | G15: =SUM(C15:F15) -> 1123637.5 | H15: =SUMIFS('Daily Issuance'!$O:$O,'Daily Issuance'!$E:$E,"Inventory",'Daily Issuance'!$B:$B,">="&DATE(2026,6,1),'Daily Issuance'!$B:$B,"<"&EDATE(DATE(2026,6,1),1)) -> 1621118 | I15: =SUMIFS('Daily Issuance'!$O:$O,'Daily Issuance'!$E:$E,"Non Inventory",'Daily Issuance'!$B:$B,">="&DATE(2026,6,1),'Daily Issuance'!$B:$B,"<"&EDATE(DATE(2026,6,1),1)) -> 801531.81 | J15: =SUMIFS('Daily Issuance'!$O:$O,'Daily Issuance'!$E:$E,"Services",'Daily Issuance'!$B:$B,">="&DATE(2026,6,1),'Daily Issuance'!$B:$B,"<"&EDATE(DATE(2026,6,1),1)) -> 398000 | K15: =SUMIFS('Daily Issuance'!$O:$O,'Daily Issuance'!$E:$E,"Patty Cash",'Daily Issuance'!$B:$B,">="&DATE(2026,6,1),'Daily Issuance'!$B:$B,"<"&EDATE(DATE(2026,6,1),1)) -> 9032.6489 | L15: =SUM(H15:K15) -> 2829682.5
B16: Jul 2026 | C16: =SUMIFS('Daily Inward'!$J:$J,'Daily Inward'!$E:$E,"Inventory",'Daily Inward'!$B:$B,">="&DATE(2026,7,1),'Daily Inward'!$B:$B,"<"&EDATE(DATE(2026,7,1),1)) -> 0 | D16: =SUMIFS('Daily Inward'!$J:$J,'Daily Inward'!$E:$E,"Non Inventory",'Daily Inward'!$B:$B,">="&DATE(2026,7,1),'Daily Inward'!$B:$B,"<"&EDATE(DATE(2026,7,1),1)) -> 0 | E16: =SUMIFS('Daily Inward'!$J:$J,'Daily Inward'!$E:$E,"Services",'Daily Inward'!$B:$B,">="&DATE(2026,7,1),'Daily Inward'!$B:$B,"<"&EDATE(DATE(2026,7,1),1)) -> 0 | F16: =SUMIFS('Daily Inward'!$J:$J,'Daily Inward'!$E:$E,"Patty Cash",'Daily Inward'!$B:$B,">="&DATE(2026,7,1),'Daily Inward'!$B:$B,"<"&EDATE(DATE(2026,7,1),1)) -> 0 | G16: =SUM(C16:F16) -> 0 | H16: =SUMIFS('Daily Issuance'!$O:$O,'Daily Issuance'!$E:$E,"Inventory",'Daily Issuance'!$B:$B,">="&DATE(2026,7,1),'Daily Issuance'!$B:$B,"<"&EDATE(DATE(2026,7,1),1)) -> 0 | I16: =SUMIFS('Daily Issuance'!$O:$O,'Daily Issuance'!$E:$E,"Non Inventory",'Daily Issuance'!$B:$B,">="&DATE(2026,7,1),'Daily Issuance'!$B:$B,"<"&EDATE(DATE(2026,7,1),1)) -> 0 | J16: =SUMIFS('Daily Issuance'!$O:$O,'Daily Issuance'!$E:$E,"Services",'Daily Issuance'!$B:$B,">="&DATE(2026,7,1),'Daily Issuance'!$B:$B,"<"&EDATE(DATE(2026,7,1),1)) -> 0 | K16: =SUMIFS('Daily Issuance'!$O:$O,'Daily Issuance'!$E:$E,"Patty Cash",'Daily Issuance'!$B:$B,">="&DATE(2026,7,1),'Daily Issuance'!$B:$B,"<"&EDATE(DATE(2026,7,1),1)) -> 0 | L16: =SUM(H16:K16) -> 0
B17: Aug 2026 | C17: =SUMIFS('Daily Inward'!$J:$J,'Daily Inward'!$E:$E,"Inventory",'Daily Inward'!$B:$B,">="&DATE(2026,8,1),'Daily Inward'!$B:$B,"<"&EDATE(DATE(2026,8,1),1)) -> 0 | D17: =SUMIFS('Daily Inward'!$J:$J,'Daily Inward'!$E:$E,"Non Inventory",'Daily Inward'!$B:$B,">="&DATE(2026,8,1),'Daily Inward'!$B:$B,"<"&EDATE(DATE(2026,8,1),1)) -> 0 | E17: =SUMIFS('Daily Inward'!$J:$J,'Daily Inward'!$E:$E,"Services",'Daily Inward'!$B:$B,">="&DATE(2026,8,1),'Daily Inward'!$B:$B,"<"&EDATE(DATE(2026,8,1),1)) -> 0 | F17: =SUMIFS('Daily Inward'!$J:$J,'Daily Inward'!$E:$E,"Patty Cash",'Daily Inward'!$B:$B,">="&DATE(2026,8,1),'Daily Inward'!$B:$B,"<"&EDATE(DATE(2026,8,1),1)) -> 0 | G17: =SUM(C17:F17) -> 0 | H17: =SUMIFS('Daily Issuance'!$O:$O,'Daily Issuance'!$E:$E,"Inventory",'Daily Issuance'!$B:$B,">="&DATE(2026,8,1),'Daily Issuance'!$B:$B,"<"&EDATE(DATE(2026,8,1),1)) -> 0 | I17: =SUMIFS('Daily Issuance'!$O:$O,'Daily Issuance'!$E:$E,"Non Inventory",'Daily Issuance'!$B:$B,">="&DATE(2026,8,1),'Daily Issuance'!$B:$B,"<"&EDATE(DATE(2026,8,1),1)) -> 0 | J17: =SUMIFS('Daily Issuance'!$O:$O,'Daily Issuance'!$E:$E,"Services",'Daily Issuance'!$B:$B,">="&DATE(2026,8,1),'Daily Issuance'!$B:$B,"<"&EDATE(DATE(2026,8,1),1)) -> 0 | K17: =SUMIFS('Daily Issuance'!$O:$O,'Daily Issuance'!$E:$E,"Patty Cash",'Daily Issuance'!$B:$B,">="&DATE(2026,8,1),'Daily Issuance'!$B:$B,"<"&EDATE(DATE(2026,8,1),1)) -> 0 | L17: =SUM(H17:K17) -> 0
B18: Sep 2026 | C18: =SUMIFS('Daily Inward'!$J:$J,'Daily Inward'!$E:$E,"Inventory",'Daily Inward'!$B:$B,">="&DATE(2026,9,1),'Daily Inward'!$B:$B,"<"&EDATE(DATE(2026,9,1),1)) -> 0 | D18: =SUMIFS('Daily Inward'!$J:$J,'Daily Inward'!$E:$E,"Non Inventory",'Daily Inward'!$B:$B,">="&DATE(2026,9,1),'Daily Inward'!$B:$B,"<"&EDATE(DATE(2026,9,1),1)) -> 0 | E18: =SUMIFS('Daily Inward'!$J:$J,'Daily Inward'!$E:$E,"Services",'Daily Inward'!$B:$B,">="&DATE(2026,9,1),'Daily Inward'!$B:$B,"<"&EDATE(DATE(2026,9,1),1)) -> 0 | F18: =SUMIFS('Daily Inward'!$J:$J,'Daily Inward'!$E:$E,"Patty Cash",'Daily Inward'!$B:$B,">="&DATE(2026,9,1),'Daily Inward'!$B:$B,"<"&EDATE(DATE(2026,9,1),1)) -> 0 | G18: =SUM(C18:F18) -> 0 | H18: =SUMIFS('Daily Issuance'!$O:$O,'Daily Issuance'!$E:$E,"Inventory",'Daily Issuance'!$B:$B,">="&DATE(2026,9,1),'Daily Issuance'!$B:$B,"<"&EDATE(DATE(2026,9,1),1)) -> 0 | I18: =SUMIFS('Daily Issuance'!$O:$O,'Daily Issuance'!$E:$E,"Non Inventory",'Daily Issuance'!$B:$B,">="&DATE(2026,9,1),'Daily Issuance'!$B:$B,"<"&EDATE(DATE(2026,9,1),1)) -> 0 | J18: =SUMIFS('Daily Issuance'!$O:$O,'Daily Issuance'!$E:$E,"Services",'Daily Issuance'!$B:$B,">="&DATE(2026,9,1),'Daily Issuance'!$B:$B,"<"&EDATE(DATE(2026,9,1),1)) -> 0 | K18: =SUMIFS('Daily Issuance'!$O:$O,'Daily Issuance'!$E:$E,"Patty Cash",'Daily Issuance'!$B:$B,">="&DATE(2026,9,1),'Daily Issuance'!$B:$B,"<"&EDATE(DATE(2026,9,1),1)) -> 0 | L18: =SUM(H18:K18) -> 0
B19: Oct 2026 | C19: =SUMIFS('Daily Inward'!$J:$J,'Daily Inward'!$E:$E,"Inventory",'Daily Inward'!$B:$B,">="&DATE(2026,10,1),'Daily Inward'!$B:$B,"<"&EDATE(DATE(2026,10,1),1)) -> 0 | D19: =SUMIFS('Daily Inward'!$J:$J,'Daily Inward'!$E:$E,"Non Inventory",'Daily Inward'!$B:$B,">="&DATE(2026,10,1),'Daily Inward'!$B:$B,"<"&EDATE(DATE(2026,10,1),1)) -> 0 | E19: =SUMIFS('Daily Inward'!$J:$J,'Daily Inward'!$E:$E,"Services",'Daily Inward'!$B:$B,">="&DATE(2026,10,1),'Daily Inward'!$B:$B,"<"&EDATE(DATE(2026,10,1),1)) -> 0 | F19: =SUMIFS('Daily Inward'!$J:$J,'Daily Inward'!$E:$E,"Patty Cash",'Daily Inward'!$B:$B,">="&DATE(2026,10,1),'Daily Inward'!$B:$B,"<"&EDATE(DATE(2026,10,1),1)) -> 0 | G19: =SUM(C19:F19) -> 0 | H19: =SUMIFS('Daily Issuance'!$O:$O,'Daily Issuance'!$E:$E,"Inventory",'Daily Issuance'!$B:$B,">="&DATE(2026,10,1),'Daily Issuance'!$B:$B,"<"&EDATE(DATE(2026,10,1),1)) -> 0 | I19: =SUMIFS('Daily Issuance'!$O:$O,'Daily Issuance'!$E:$E,"Non Inventory",'Daily Issuance'!$B:$B,">="&DATE(2026,10,1),'Daily Issuance'!$B:$B,"<"&EDATE(DATE(2026,10,1),1)) -> 0 | J19: =SUMIFS('Daily Issuance'!$O:$O,'Daily Issuance'!$E:$E,"Services",'Daily Issuance'!$B:$B,">="&DATE(2026,10,1),'Daily Issuance'!$B:$B,"<"&EDATE(DATE(2026,10,1),1)) -> 0 | K19: =SUMIFS('Daily Issuance'!$O:$O,'Daily Issuance'!$E:$E,"Patty Cash",'Daily Issuance'!$B:$B,">="&DATE(2026,10,1),'Daily Issuance'!$B:$B,"<"&EDATE(DATE(2026,10,1),1)) -> 0 | L19: =SUM(H19:K19) -> 0
B20: Nov 2026 | C20: =SUMIFS('Daily Inward'!$J:$J,'Daily Inward'!$E:$E,"Inventory",'Daily Inward'!$B:$B,">="&DATE(2026,11,1),'Daily Inward'!$B:$B,"<"&EDATE(DATE(2026,11,1),1)) -> 0 | D20: =SUMIFS('Daily Inward'!$J:$J,'Daily Inward'!$E:$E,"Non Inventory",'Daily Inward'!$B:$B,">="&DATE(2026,11,1),'Daily Inward'!$B:$B,"<"&EDATE(DATE(2026,11,1),1)) -> 0 | E20: =SUMIFS('Daily Inward'!$J:$J,'Daily Inward'!$E:$E,"Services",'Daily Inward'!$B:$B,">="&DATE(2026,11,1),'Daily Inward'!$B:$B,"<"&EDATE(DATE(2026,11,1),1)) -> 0 | F20: =SUMIFS('Daily Inward'!$J:$J,'Daily Inward'!$E:$E,"Patty Cash",'Daily Inward'!$B:$B,">="&DATE(2026,11,1),'Daily Inward'!$B:$B,"<"&EDATE(DATE(2026,11,1),1)) -> 0 | G20: =SUM(C20:F20) -> 0 | H20: =SUMIFS('Daily Issuance'!$O:$O,'Daily Issuance'!$E:$E,"Inventory",'Daily Issuance'!$B:$B,">="&DATE(2026,11,1),'Daily Issuance'!$B:$B,"<"&EDATE(DATE(2026,11,1),1)) -> 0 | I20: =SUMIFS('Daily Issuance'!$O:$O,'Daily Issuance'!$E:$E,"Non Inventory",'Daily Issuance'!$B:$B,">="&DATE(2026,11,1),'Daily Issuance'!$B:$B,"<"&EDATE(DATE(2026,11,1),1)) -> 0 | J20: =SUMIFS('Daily Issuance'!$O:$O,'Daily Issuance'!$E:$E,"Services",'Daily Issuance'!$B:$B,">="&DATE(2026,11,1),'Daily Issuance'!$B:$B,"<"&EDATE(DATE(2026,11,1),1)) -> 0 | K20: =SUMIFS('Daily Issuance'!$O:$O,'Daily Issuance'!$E:$E,"Patty Cash",'Daily Issuance'!$B:$B,">="&DATE(2026,11,1),'Daily Issuance'!$B:$B,"<"&EDATE(DATE(2026,11,1),1)) -> 0 | L20: =SUM(H20:K20) -> 0
B21: Dec 2026 | C21: =SUMIFS('Daily Inward'!$J:$J,'Daily Inward'!$E:$E,"Inventory",'Daily Inward'!$B:$B,">="&DATE(2026,12,1),'Daily Inward'!$B:$B,"<"&EDATE(DATE(2026,12,1),1)) -> 0 | D21: =SUMIFS('Daily Inward'!$J:$J,'Daily Inward'!$E:$E,"Non Inventory",'Daily Inward'!$B:$B,">="&DATE(2026,12,1),'Daily Inward'!$B:$B,"<"&EDATE(DATE(2026,12,1),1)) -> 0 | E21: =SUMIFS('Daily Inward'!$J:$J,'Daily Inward'!$E:$E,"Services",'Daily Inward'!$B:$B,">="&DATE(2026,12,1),'Daily Inward'!$B:$B,"<"&EDATE(DATE(2026,12,1),1)) -> 0 | F21: =SUMIFS('Daily Inward'!$J:$J,'Daily Inward'!$E:$E,"Patty Cash",'Daily Inward'!$B:$B,">="&DATE(2026,12,1),'Daily Inward'!$B:$B,"<"&EDATE(DATE(2026,12,1),1)) -> 0 | G21: =SUM(C21:F21) -> 0 | H21: =SUMIFS('Daily Issuance'!$O:$O,'Daily Issuance'!$E:$E,"Inventory",'Daily Issuance'!$B:$B,">="&DATE(2026,12,1),'Daily Issuance'!$B:$B,"<"&EDATE(DATE(2026,12,1),1)) -> 0 | I21: =SUMIFS('Daily Issuance'!$O:$O,'Daily Issuance'!$E:$E,"Non Inventory",'Daily Issuance'!$B:$B,">="&DATE(2026,12,1),'Daily Issuance'!$B:$B,"<"&EDATE(DATE(2026,12,1),1)) -> 0 | J21: =SUMIFS('Daily Issuance'!$O:$O,'Daily Issuance'!$E:$E,"Services",'Daily Issuance'!$B:$B,">="&DATE(2026,12,1),'Daily Issuance'!$B:$B,"<"&EDATE(DATE(2026,12,1),1)) -> 0 | K21: =SUMIFS('Daily Issuance'!$O:$O,'Daily Issuance'!$E:$E,"Patty Cash",'Daily Issuance'!$B:$B,">="&DATE(2026,12,1),'Daily Issuance'!$B:$B,"<"&EDATE(DATE(2026,12,1),1)) -> 0 | L21: =SUM(H21:K21) -> 0
B22: GRAND TOTAL | C22: =SUM(C14:C21) -> 1086500 | D22: =SUM(D14:D21) -> 1734685.8 | E22: =SUM(E14:E21) -> 1183200 | F22: =SUM(F14:F21) -> 23751.208 | G22: =SUM(G14:G21) -> 4028137 | H22: =SUM(H14:H21) -> 3338614 | I22: =SUM(I14:I21) -> 1153611.8 | J22: =SUM(J14:J21) -> 1183200 | ... L22: =SUM(L14:L21) -> 5700567.4
B24: MONTHLY MACHINE HIGH / LOW AUTO SYSTEM
B26: Total Machine Work | C26: Active Months | D26: Highest Month | E26: Lowest Active Month | F26: Machines Tracked | G26: Months Needing Focus | I26: How to read
B27: =SUM('Machine Issuance Dashboard'!$AP$6:$AP$58) -> 5691603.8 | C27: =COUNTIF(C31:C38,">0") -> 2 | D27: =INDEX(B31:B38,MATCH(MAX(C31:C38),C31:C38,0)) -> May | E27: {=IFERROR(INDEX(B31:B38,MATCH(MIN(_xlfn._xlws.FILTER(C31:C38,C31:C38>0)),C31:C38,0)),"No Data")} -> Jun | F27: =COUNTA('Machine Issuance Dashboard'!$A$6:$A$57) -> 52 | G27: =COUNTIF(J31:J38,"Focus") -> 2 | I27: High machine | J27: Month mein sab se zyada work/spend | K27: Red flag | L27: Check reason / maintenance
I28: Low active machine | J28: Zero ko ignore karke lowest active | K28: Amber | L28: Verify usage / idle issue
I29: No Data | J29: Month mein machine work nahi mila | K29: Gray | L29: Source update required
B30: Month | C30: Total Work | D30: Most Work Machine | E30: Most Amount | F30: Least Active Machine | G30: Least Amount | I30: Top Share | J30: Focus Level | K30: Quick Action | L30: Data Check
B31: May | C31: =SUM('Machine Issuance Dashboard'!$F$6:$F$57) -> 2863371 | D31: =IF(C31=0,"No Data",INDEX('Machine Issuance Dashboard'!$A$6:$A$57,MATCH(MAX('Machine Issuance Dashboard'!$F$6:$F$57),'Machine Issuance Dashboard'!$F$6:$F$57,0))) -> Auto Fryer | E31: =IF(C31=0,0,MAX('Machine Issuance Dashboard'!$F$6:$F$57)) -> 1232577 | F31: {=IF(C31=0,"No Data",IFERROR(INDEX('Machine Issuance Dashboard'!$A$6:$A$57,MATCH(MIN(_xlfn._xlws.FILTER('Machine Issuance Dashboard'!$F$6:$F$57,'Machine Issuance Dashboard'!$F$6:$F$57>0)),'Machine Issuance Dashboard'!$F$6:$F$57,0)),"No Active"))} -> DB Water Chiller | G31: {=IF(C31=0,0,IFERROR(MIN(_xlfn._xlws.FILTER('Machine Issuance Dashboard'!$F$6:$F$57,'Machine Issuance Dashboard'!$F$6:$F$57>0)),0))} -> 183 | I31: =IF(C31=0,0,E31/C31) -> 0.4304636 | J31: =IF(C31=0,"No Data",IF(I31>=40%,"Focus",IF(I31>=25%,"Watch","Normal"))) -> Focus | K31: =IF(J31="Focus","Check top machine immediately",IF(J31="Watch","Monitor monthly",IF(J31="Normal","OK","Update source"))) -> Check top machine immediately | L31: =IF(C31=0,"No Data","OK") -> OK
B32: Jun | C32: =SUM('Machine Issuance Dashboard'!$K$6:$K$57) -> 2303222 | D32: =IF(C32=0,"No Data",INDEX('Machine Issuance Dashboard'!$A$6:$A$57,MATCH(MAX('Machine Issuance Dashboard'!$K$6:$K$57),'Machine Issuance Dashboard'!$K$6:$K$57,0))) -> Ishida No: 02 | E32: =IF(C32=0,0,MAX('Machine Issuance Dashboard'!$K$6:$K$57)) -> 1007768 | F32: {=IF(C32=0,"No Data",IFERROR(INDEX('Machine Issuance Dashboard'!$A$6:$A$57,MATCH(MIN(_xlfn._xlws.FILTER('Machine Issuance Dashboard'!$K$6:$K$57,'Machine Issuance Dashboard'!$K$6:$K$57>0)),'Machine Issuance Dashboard'!$K$6:$K$57,0)),"No Active"))} -> Hand Pallet | G32: {=IF(C32=0,0,IFERROR(MIN(_xlfn._xlws.FILTER('Machine Issuance Dashboard'!$K$6:$K$57,'Machine Issuance Dashboard'!$K$6:$K$57>0)),0))} -> 45 | I32: =IF(C32=0,0,E32/C32) -> 0.43754705 | J32: =IF(C32=0,"No Data",IF(I32>=40%,"Focus",IF(I32>=25%,"Watch","Normal"))) -> Focus | K32: =IF(J32="Focus","Check top machine immediately",IF(J32="Watch","Monitor monthly",IF(J32="Normal","OK","Update source"))) -> Check top machine immediately | L32: =IF(C32=0,"No Data","OK") -> OK
B33: Jul | C33: =SUM('Machine Issuance Dashboard'!$P$6:$P$57) -> 0 | D33: =IF(C33=0,"No Data",INDEX('Machine Issuance Dashboard'!$A$6:$A$57,MATCH(MAX('Machine Issuance Dashboard'!$P$6:$P$57),'Machine Issuance Dashboard'!$P$6:$P$57,0))) -> No Data | E33: =IF(C33=0,0,MAX('Machine Issuance Dashboard'!$P$6:$P$57)) -> 0 | F33: {=IF(C33=0,"No Data",IFERROR(INDEX('Machine Issuance Dashboard'!$A$6:$A$57,MATCH(MIN(_xlfn._xlws.FILTER('Machine Issuance Dashboard'!$P$6:$P$57,'Machine Issuance Dashboard'!$P$6:$P$57>0)),'Machine Issuance Dashboard'!$P$6:$P$57,0)),"No Active"))} -> No Data | G33: {=IF(C33=0,0,IFERROR(MIN(_xlfn._xlws.FILTER('Machine Issuance Dashboard'!$P$6:$P$57,'Machine Issuance Dashboard'!$P$6:$P$57>0)),0))} -> 0 | I33: =IF(C33=0,0,E33/C33) -> 0 | J33: =IF(C33=0,"No Data",IF(I33>=40%,"Focus",IF(I33>=25%,"Watch","Normal"))) -> No Data | K33: =IF(J33="Focus","Check top machine immediately",IF(J33="Watch","Monitor monthly",IF(J33="Normal","OK","Update source"))) -> Update source | L33: =IF(C33=0,"No Data","OK") -> No Data
B34: Aug | C34: =SUM('Machine Issuance Dashboard'!$U$6:$U$57) -> 0 | D34: =IF(C34=0,"No Data",INDEX('Machine Issuance Dashboard'!$A$6:$A$57,MATCH(MAX('Machine Issuance Dashboard'!$U$6:$U$57),'Machine Issuance Dashboard'!$U$6:$U$57,0))) -> No Data | E34: =IF(C34=0,0,MAX('Machine Issuance Dashboard'!$U$6:$U$57)) -> 0 | F34: {=IF(C34=0,"No Data",IFERROR(INDEX('Machine Issuance Dashboard'!$A$6:$A$57,MATCH(MIN(_xlfn._xlws.FILTER('Machine Issuance Dashboard'!$U$6:$U$57,'Machine Issuance Dashboard'!$U$6:$U$57>0)),'Machine Issuance Dashboard'!$U$6:$U$57,0)),"No Active"))} -> No Data | G34: {=IF(C34=0,0,IFERROR(MIN(_xlfn._xlws.FILTER('Machine Issuance Dashboard'!$U$6:$U$57,'Machine Issuance Dashboard'!$U$6:$U$57>0)),0))} -> 0 | I34: =IF(C34=0,0,E34/C34) -> 0 | J34: =IF(C34=0,"No Data",IF(I34>=40%,"Focus",IF(I34>=25%,"Watch","Normal"))) -> No Data | K34: =IF(J34="Focus","Check top machine immediately",IF(J34="Watch","Monitor monthly",IF(J34="Normal","OK","Update source"))) -> Update source | L34: =IF(C34=0,"No Data","OK") -> No Data
B35: Sep | C35: =SUM('Machine Issuance Dashboard'!$Z$6:$Z$57) -> 0 | D35: =IF(C35=0,"No Data",INDEX('Machine Issuance Dashboard'!$A$6:$A$57,MATCH(MAX('Machine Issuance Dashboard'!$Z$6:$Z$57),'Machine Issuance Dashboard'!$Z$6:$Z$57,0))) -> No Data | E35: =IF(C35=0,0,MAX('Machine Issuance Dashboard'!$Z$6:$Z$57)) -> 0 | F35: {=IF(C35=0,"No Data",IFERROR(INDEX('Machine Issuance Dashboard'!$A$6:$A$57,MATCH(MIN(_xlfn._xlws.FILTER('Machine Issuance Dashboard'!$Z$6:$Z$57,'Machine Issuance Dashboard'!$Z$6:$Z$57>0)),'Machine Issuance Dashboard'!$Z$6:$Z$57,0)),"No Active"))} -> No Data | G35: {=IF(C35=0,0,IFERROR(MIN(_xlfn._xlws.FILTER('Machine Issuance Dashboard'!$Z$6:$Z$57,'Machine Issuance Dashboard'!$Z$6:$Z$57>0)),0))} -> 0 | I35: =IF(C35=0,0,E35/C35) -> 0 | J35: =IF(C35=0,"No Data",IF(I35>=40%,"Focus",IF(I35>=25%,"Watch","Normal"))) -> No Data | K35: =IF(J35="Focus","Check top machine immediately",IF(J35="Watch","Monitor monthly",IF(J35="Normal","OK","Update source"))) -> Update source | L35: =IF(C35=0,"No Data","OK") -> No Data
B36: Oct | C36: =SUM('Machine Issuance Dashboard'!$AE$6:$AE$57) -> 0 | D36: =IF(C36=0,"No Data",INDEX('Machine Issuance Dashboard'!$A$6:$A$57,MATCH(MAX('Machine Issuance Dashboard'!$AE$6:$AE$57),'Machine Issuance Dashboard'!$AE$6:$AE$57,0))) -> No Data | E36: =IF(C36=0,0,MAX('Machine Issuance Dashboard'!$AE$6:$AE$57)) -> 0 | F36: {=IF(C36=0,"No Data",IFERROR(INDEX('Machine Issuance Dashboard'!$A$6:$A$57,MATCH(MIN(_xlfn._xlws.FILTER('Machine Issuance Dashboard'!$AE$6:$AE$57,'Machine Issuance Dashboard'!$AE$6:$AE$57>0)),'Machine Issuance Dashboard'!$AE$6:$AE$57,0)),"No Active"))} -> No Data | G36: {=IF(C36=0,0,IFERROR(MIN(_xlfn._xlws.FILTER('Machine Issuance Dashboard'!$AE$6:$AE$57,'Machine Issuance Dashboard'!$AE$6:$AE$57>0)),0))} -> 0 | I36: =IF(C36=0,0,E36/C36) -> 0 | J36: =IF(C36=0,"No Data",IF(I36>=40%,"Focus",IF(I36>=25%,"Watch","Normal"))) -> No Data | K36: =IF(J36="Focus","Check top machine immediately",IF(J36="Watch","Monitor monthly",IF(J36="Normal","OK","Update source"))) -> Update source | L36: =IF(C36=0,"No Data","OK") -> No Data
B37: Nov | C37: =SUM('Machine Issuance Dashboard'!$AJ$6:$AJ$57) -> 0 | D37: =IF(C37=0,"No Data",INDEX('Machine Issuance Dashboard'!$A$6:$A$57,MATCH(MAX('Machine Issuance Dashboard'!$AJ$6:$AJ$57),'Machine Issuance Dashboard'!$AJ$6:$AJ$57,0))) -> No Data | E37: =IF(C37=0,0,MAX('Machine Issuance Dashboard'!$AJ$6:$AJ$57)) -> 0 | F37: {=IF(C37=0,"No Data",IFERROR(INDEX('Machine Issuance Dashboard'!$A$6:$A$57,MATCH(MIN(_xlfn._xlws.FILTER('Machine Issuance Dashboard'!$AJ$6:$AJ$57,'Machine Issuance Dashboard'!$AJ$6:$AJ$57>0)),'Machine Issuance Dashboard'!$AJ$6:$AJ$57,0)),"No Active"))} -> No Data | G37: {=IF(C37=0,0,IFERROR(MIN(_xlfn._xlws.FILTER('Machine Issuance Dashboard'!$AJ$6:$AJ$57,'Machine Issuance Dashboard'!$AJ$6:$AJ$57>0)),0))} -> 0 | I37: =IF(C37=0,0,E37/C37) -> 0 | J37: =IF(C37=0,"No Data",IF(I37>=40%,"Focus",IF(I37>=25%,"Watch","Normal"))) -> No Data | K37: =IF(J37="Focus","Check top machine immediately",IF(J37="Watch","Monitor monthly",IF(J37="Normal","OK","Update source"))) -> Update source | L37: =IF(C37=0,"No Data","OK") -> No Data
B38: Dec | C38: =SUM('Machine Issuance Dashboard'!$AO$6:$AO$57) -> 0 | D38: =IF(C38=0,"No Data",INDEX('Machine Issuance Dashboard'!$A$6:$A$57,MATCH(MAX('Machine Issuance Dashboard'!$AO$6:$AO$57),'Machine Issuance Dashboard'!$AO$6:$AO$57,0))) -> No Data | E38: =IF(C38=0,0,MAX('Machine Issuance Dashboard'!$AO$6:$AO$57)) -> 0 | F38: {=IF(C38=0,"No Data",IFERROR(INDEX('Machine Issuance Dashboard'!$A$6:$A$57,MATCH(MIN(_xlfn._xlws.FILTER('Machine Issuance Dashboard'!$AO$6:$AO$57,'Machine Issuance Dashboard'!$AO$6:$AO$57>0)),'Machine Issuance Dashboard'!$AO$6:$AO$57,0)),"No Active"))} -> No Data | G38: {=IF(C38=0,0,IFERROR(MIN(_xlfn._xlws.FILTER('Machine Issuance Dashboard'!$AO$6:$AO$57,'Machine Issuance Dashboard'!$AO$6:$AO$57>0)),0))} -> 0 | I38: =IF(C38=0,0,E38/C38) -> 0 | J38: =IF(C38=0,"No Data",IF(I38>=40%,"Focus",IF(I38>=25%,"Watch","Normal"))) -> No Data | K38: =IF(J38="Focus","Check top machine immediately",IF(J38="Watch","Monitor monthly",IF(J38="Normal","OK","Update source"))) -> Update source | L38: =IF(C38=0,"No Data","OK") -> No Data
B41: TOP 5 MACHINES - FULL YEAR | I41: LOW / IDLE WATCHLIST
B42: Rank | C42: Machine | D42: Year Total | E42: Share | F42: Major Month | G42: Action | I42: Machine | J42: Year Total | K42: Active Months | L42: Status
B43: 1 | C43: =INDEX('Machine Issuance Dashboard'!$A$6:$A$57,MATCH(LARGE('Machine Issuance Dashboard'!$AP$6:$AP$57,B43),'Machine Issuance Dashboard'!$AP$6:$AP$57,0)) -> Auto Fryer | D43: =LARGE('Machine Issuance Dashboard'!$AP$6:$AP$57,B43) -> 1232577 | E43: =D43/$B$27 -> 0.21656058 | F43: {=_xlfn.LET(_xlpm.mach,C43,_xlpm.rowNo,MATCH(_xlpm.mach,'Machine Issuance Dashboard'!$A$6:$A$57,0),_xlpm.vals,CHOOSE({1,2,3,4,5,6,7,8},INDEX('Machine Issuance Dashboard'!$F$6:$F$57,_xlpm.rowNo),INDEX('Machine Issuance Dashboard'!$K$6:$K$57,_xlpm.rowNo),INDEX('Machine Issuance Dashboard'!$P$6:$P$57,_xlpm.rowNo),INDEX('Machine Issuance Dashboard'!$U$6:$U$57,_xlpm.rowNo),INDEX('Machine Issuance Dashboard'!$Z$6:$Z$57,_xlpm.rowNo),INDEX('Machine Issuance Dashboard'!$AE$6:$AE$57,_xlpm.rowNo),INDEX('Machine Issuance Dashboard'!$AJ$6:$AJ$57,_xlpm.rowNo),INDEX('Machine Issuance Dashboard'!$AO$6:$AO$57,_xlpm.rowNo)),INDEX({"May","Jun","Jul","Aug","Sep","Oct","Nov","Dec"},MATCH(MAX(_xlpm.vals),_xlpm.vals,0)))} -> May | G43: =IF(E43>=20%,"Priority check",IF(E43>=10%,"Watch","Normal")) -> Priority check | I43: {=IFERROR(INDEX(_xlfn._xlws.FILTER('Machine Issuance Dashboard'!$A$6:$A$57,'Machine Issuance Dashboard'!$AP$6:$AP$57>0),MATCH(SMALL(_xlfn._xlws.FILTER('Machine Issuance Dashboard'!$AP$6:$AP$57,'Machine Issuance Dashboard'!$AP$6:$AP$57>0),1),_xlfn._xlws.FILTER('Machine Issuance Dashboard'!$AP$6:$AP$57,'Machine Issuance Dashboard'!$AP$6:$AP$57>0),0)),"No Data")} -> Batch Fryer No: 02 | J43: =IFERROR(INDEX('Machine Issuance Dashboard'!$AP$6:$AP$57,MATCH(I43,'Machine Issuance Dashboard'!$A$6:$A$57,0)),0) -> 230 | K43: =IF(I43="No Data",0,--(INDEX('Machine Issuance Dashboard'!$F$6:$F$57,MATCH(I43,'Machine Issuance Dashboard'!$A$6:$A$57,0))>0)+--(INDEX('Machine Issuance Dashboard'!$K$6:$K$57,MATCH(I43,'Machine Issuance Dashboard'!$A$6:$A$57,0))>0)+--(INDEX('Machine Issuance Dashboard'!$P$6:$P$57,MATCH(I43,'Machine Issuance Dashboard'!$A$6:$A$57,0))>0)+--(INDEX('Machine Issuance Dashboard'!$U$6:$U$57,MATCH(I43,'Machine Issuance Dashboard'!$A$6:$A$57,0))>0)+--(INDEX('Machine Issuance Dashboard'!$Z$6:$Z$57,MATCH(I43,'Machine Issuance Dashboard'!$A$6:$A$57,0))>0)+--(INDEX('Machine Issuance Dashboard'!$AE$6:$AE$57,MATCH(I43,'Machine Issuance Dashboard'!$A$6:$A$57,0))>0)+--(INDEX('Machine Issuance Dashboard'!$AJ$6:$AJ$57,MATCH(I43,'Machine Issuance Dashboard'!$A$6:$A$57,0))>0)+--(INDEX('Machine Issuance Dashboard'!$AO$6:$AO$57,MATCH(I43,'Machine Issuance Dashboard'!$A$6:$A$57,0))>0)) -> 1 | L43: =IF(J43=0,"Idle",IF(K43<=1,"Low Use","Active")) -> Low Use
B44: 2 | C44: =INDEX('Machine Issuance Dashboard'!$A$6:$A$57,MATCH(LARGE('Machine Issuance Dashboard'!$AP$6:$AP$57,B44),'Machine Issuance Dashboard'!$AP$6:$AP$57,0)) -> Ishida No: 02 | D44: =LARGE('Machine Issuance Dashboard'!$AP$6:$AP$57,B44) -> 1017774 | E44: =D44/$B$27 -> 0.17882025 | F44: {=_xlfn.LET(_xlpm.mach,C44,_xlpm.rowNo,MATCH(_xlpm.mach,'Machine Issuance Dashboard'!$A$6:$A$57,0),_xlpm.vals,CHOOSE({1,2,3,4,5,6,7,8},INDEX('Machine Issuance Dashboard'!$F$6:$F$57,_xlpm.rowNo),INDEX('Machine Issuance Dashboard'!$K$6:$K$57,_xlpm.rowNo),INDEX('Machine Issuance Dashboard'!$P$6:$P$57,_xlpm.rowNo),INDEX('Machine Issuance Dashboard'!$U$6:$U$57,_xlpm.rowNo),INDEX('Machine Issuance Dashboard'!$Z$6:$Z$57,_xlpm.rowNo),INDEX('Machine Issuance Dashboard'!$AE$6:$AE$57,_xlpm.rowNo),INDEX('Machine Issuance Dashboard'!$AJ$6:$AJ$57,_xlpm.rowNo),INDEX('Machine Issuance Dashboard'!$AO$6:$AO$57,_xlpm.rowNo)),INDEX({"May","Jun","Jul","Aug","Sep","Oct","Nov","Dec"},MATCH(MAX(_xlpm.vals),_xlpm.vals,0)))} -> Jun | G44: =IF(E44>=20%,"Priority check",IF(E44>=10%,"Watch","Normal")) -> Watch | I44: {=IFERROR(INDEX(_xlfn._xlws.FILTER('Machine Issuance Dashboard'!$A$6:$A$57,'Machine Issuance Dashboard'!$AP$6:$AP$57>0),MATCH(SMALL(_xlfn._xlws.FILTER('Machine Issuance Dashboard'!$AP$6:$AP$57,'Machine Issuance Dashboard'!$AP$6:$AP$57>0),2),_xlfn._xlws.FILTER('Machine Issuance Dashboard'!$AP$6:$AP$57,'Machine Issuance Dashboard'!$AP$6:$AP$57>0),0)),"No Data")} -> Korea No: 04 | J44: =IFERROR(INDEX('Machine Issuance Dashboard'!$AP$6:$AP$57,MATCH(I44,'Machine Issuance Dashboard'!$A$6:$A$57,0)),0) -> 450 | K44: =IF(I44="No Data",0,--(INDEX('Machine Issuance Dashboard'!$F$6:$F$57,MATCH(I44,'Machine Issuance Dashboard'!$A$6:$A$57,0))>0)+--(INDEX('Machine Issuance Dashboard'!$K$6:$K$57,MATCH(I44,'Machine Issuance Dashboard'!$A$6:$A$57,0))>0)+--(INDEX('Machine Issuance Dashboard'!$P$6:$P$57,MATCH(I44,'Machine Issuance Dashboard'!$A$6:$A$57,0))>0)+--(INDEX('Machine Issuance Dashboard'!$U$6:$U$57,MATCH(I44,'Machine Issuance Dashboard'!$A$6:$A$57,0))>0)+--(INDEX('Machine Issuance Dashboard'!$Z$6:$Z$57,MATCH(I44,'Machine Issuance Dashboard'!$A$6:$A$57,0))>0)+--(INDEX('Machine Issuance Dashboard'!$AE$6:$AE$57,MATCH(I44,'Machine Issuance Dashboard'!$A$6:$A$57,0))>0)+--(INDEX('Machine Issuance Dashboard'!$AJ$6:$AJ$57,MATCH(I44,'Machine Issuance Dashboard'!$A$6:$A$57,0))>0)+--(INDEX('Machine Issuance Dashboard'!$AO$6:$AO$57,MATCH(I44,'Machine Issuance Dashboard'!$A$6:$A$57,0))>0)) -> 2 | L44: =IF(J44=0,"Idle",IF(K44<=1,"Low Use","Active")) -> Active
B45: 3 | C45: =INDEX('Machine Issuance Dashboard'!$A$6:$A$57,MATCH(LARGE('Machine Issuance Dashboard'!$AP$6:$AP$57,B45),'Machine Issuance Dashboard'!$AP$6:$AP$57,0)) -> Ishida No: 14 | D45: =LARGE('Machine Issuance Dashboard'!$AP$6:$AP$57,B45) -> 501227 | E45: =D45/$B$27 -> 0.088064281 | F45: {=_xlfn.LET(_xlpm.mach,C45,_xlpm.rowNo,MATCH(_xlpm.mach,'Machine Issuance Dashboard'!$A$6:$A$57,0),_xlpm.vals,CHOOSE({1,2,3,4,5,6,7,8},INDEX('Machine Issuance Dashboard'!$F$6:$F$57,_xlpm.rowNo),INDEX('Machine Issuance Dashboard'!$K$6:$K$57,_xlpm.rowNo),INDEX('Machine Issuance Dashboard'!$P$6:$P$57,_xlpm.rowNo),INDEX('Machine Issuance Dashboard'!$U$6:$U$57,_xlpm.rowNo),INDEX('Machine Issuance Dashboard'!$Z$6:$Z$57,_xlpm.rowNo),INDEX('Machine Issuance Dashboard'!$AE$6:$AE$57,_xlpm.rowNo),INDEX('Machine Issuance Dashboard'!$AJ$6:$AJ$57,_xlpm.rowNo),INDEX('Machine Issuance Dashboard'!$AO$6:$AO$57,_xlpm.rowNo)),INDEX({"May","Jun","Jul","Aug","Sep","Oct","Nov","Dec"},MATCH(MAX(_xlpm.vals),_xlpm.vals,0)))} -> Jun | G45: =IF(E45>=20%,"Priority check",IF(E45>=10%,"Watch","Normal")) -> Normal | I45: {=IFERROR(INDEX(_xlfn._xlws.FILTER('Machine Issuance Dashboard'!$A$6:$A$57,'Machine Issuance Dashboard'!$AP$6:$AP$57>0),MATCH(SMALL(_xlfn._xlws.FILTER('Machine Issuance Dashboard'!$AP$6:$AP$57,'Machine Issuance Dashboard'!$AP$6:$AP$57>0),3),_xlfn._xlws.FILTER('Machine Issuance Dashboard'!$AP$6:$AP$57,'Machine Issuance Dashboard'!$AP$6:$AP$57>0),0)),"No Data")} -> Sama No: 04 | J45: =IFERROR(INDEX('Machine Issuance Dashboard'!$AP$6:$AP$57,MATCH(I45,'Machine Issuance Dashboard'!$A$6:$A$57,0)),0) -> 900 | K45: =IF(I45="No Data",0,--(INDEX('Machine Issuance Dashboard'!$F$6:$F$57,MATCH(I45,'Machine Issuance Dashboard'!$A$6:$A$57,0))>0)+--(INDEX('Machine Issuance Dashboard'!$K$6:$K$57,MATCH(I45,'Machine Issuance Dashboard'!$A$6:$A$57,0))>0)+--(INDEX('Machine Issuance Dashboard'!$P$6:$P$57,MATCH(I45,'Machine Issuance Dashboard'!$A$6:$A$57,0))>0)+--(INDEX('Machine Issuance Dashboard'!$U$6:$U$57,MATCH(I45,'Machine Issuance Dashboard'!$A$6:$A$57,0))>0)+--(INDEX('Machine Issuance Dashboard'!$Z$6:$Z$57,MATCH(I45,'Machine Issuance Dashboard'!$A$6:$A$57,0))>0)+--(INDEX('Machine Issuance Dashboard'!$AE$6:$AE$57,MATCH(I45,'Machine Issuance Dashboard'!$A$6:$A$57,0))>0)+--(INDEX('Machine Issuance Dashboard'!$AJ$6:$AJ$57,MATCH(I45,'Machine Issuance Dashboard'!$A$6:$A$57,0))>0)+--(INDEX('Machine Issuance Dashboard'!$AO$6:$AO$57,MATCH(I45,'Machine Issuance Dashboard'!$A$6:$A$57,0))>0)) -> 1 | L45: =IF(J45=0,"Idle",IF(K45<=1,"Low Use","Active")) -> Low Use
B46: 4 | C46: =INDEX('Machine Issuance Dashboard'!$A$6:$A$57,MATCH(LARGE('Machine Issuance Dashboard'!$AP$6:$AP$57,B46),'Machine Issuance Dashboard'!$AP$6:$AP$57,0)) -> LPG Plant | D46: =LARGE('Machine Issuance Dashboard'!$AP$6:$AP$57,B46) -> 440000 | E46: =D46/$B$27 -> 0.077306857 | F46: {=_xlfn.LET(_xlpm.mach,C46,_xlpm.rowNo,MATCH(_xlpm.mach,'Machine Issuance Dashboard'!$A$6:$A$57,0),_xlpm.vals,CHOOSE({1,2,3,4,5,6,7,8},INDEX('Machine Issuance Dashboard'!$F$6:$F$57,_xlpm.rowNo),INDEX('Machine Issuance Dashboard'!$K$6:$K$57,_xlpm.rowNo),INDEX('Machine Issuance Dashboard'!$P$6:$P$57,_xlpm.rowNo),INDEX('Machine Issuance Dashboard'!$U$6:$U$57,_xlpm.rowNo),INDEX('Machine Issuance Dashboard'!$Z$6:$Z$57,_xlpm.rowNo),INDEX('Machine Issuance Dashboard'!$AE$6:$AE$57,_xlpm.rowNo),INDEX('Machine Issuance Dashboard'!$AJ$6:$AJ$57,_xlpm.rowNo),INDEX('Machine Issuance Dashboard'!$AO$6:$AO$57,_xlpm.rowNo)),INDEX({"May","Jun","Jul","Aug","Sep","Oct","Nov","Dec"},MATCH(MAX(_xlpm.vals),_xlpm.vals,0)))} -> May | G46: =IF(E46>=20%,"Priority check",IF(E46>=10%,"Watch","Normal")) -> Normal | I46: {=IFERROR(INDEX(_xlfn._xlws.FILTER('Machine Issuance Dashboard'!$A$6:$A$57,'Machine Issuance Dashboard'!$AP$6:$AP$57>0),MATCH(SMALL(_xlfn._xlws.FILTER('Machine Issuance Dashboard'!$AP$6:$AP$57,'Machine Issuance Dashboard'!$AP$6:$AP$57>0),4),_xlfn._xlws.FILTER('Machine Issuance Dashboard'!$AP$6:$AP$57,'Machine Issuance Dashboard'!$AP$6:$AP$57>0),0)),"No Data")} -> Workshop | J46: =IFERROR(INDEX('Machine Issuance Dashboard'!$AP$6:$AP$57,MATCH(I46,'Machine Issuance Dashboard'!$A$6:$A$57,0)),0) -> 1010 | K46: =IF(I46="No Data",0,--(INDEX('Machine Issuance Dashboard'!$F$6:$F$57,MATCH(I46,'Machine Issuance Dashboard'!$A$6:$A$57,0))>0)+--(INDEX('Machine Issuance Dashboard'!$K$6:$K$57,MATCH(I46,'Machine Issuance Dashboard'!$A$6:$A$57,0))>0)+--(INDEX('Machine Issuance Dashboard'!$P$6:$P$57,MATCH(I46,'Machine Issuance Dashboard'!$A$6:$A$57,0))>0)+--(INDEX('Machine Issuance Dashboard'!$U$6:$U$57,MATCH(I46,'Machine Issuance Dashboard'!$A$6:$A$57,0))>0)+--(INDEX('Machine Issuance Dashboard'!$Z$6:$Z$57,MATCH(I46,'Machine Issuance Dashboard'!$A$6:$A$57,0))>0)+--(INDEX('Machine Issuance Dashboard'!$AE$6:$AE$57,MATCH(I46,'Machine Issuance Dashboard'!$A$6:$A$57,0))>0)+--(INDEX('Machine Issuance Dashboard'!$AJ$6:$AJ$57,MATCH(I46,'Machine Issuance Dashboard'!$A$6:$A$57,0))>0)+--(INDEX('Machine Issuance Dashboard'!$AO$6:$AO$57,MATCH(I46,'Machine Issuance Dashboard'!$A$6:$A$57,0))>0)) -> 1 | L46: =IF(J46=0,"Idle",IF(K46<=1,"Low Use","Active")) -> Low Use
...

Sheet Machine Issuance Dashboard
A1: Machine Wise Issuance Dashboard
A2: Inventory + Non Inventory issuance value by Equipment/Machine Issuance from May 2026 to Dec 2026
A3: Machine Name | B3: May-2026 | G3: Jun-2026 | L3: Jul-2026 | Q3: Aug-2026 | V3: Sep-2026 | AA3: Oct-2026 | AF3: Nov-2026 | AK3: Dec-2026 | AP3: Year Total
B4: 46143 | C4: 46143 | D4: 46143 | E4: 46143 | F4: 46143 | G4: 46174 | H4: 46174 | I4: 46174 | J4: 46174 | K4: 46174 | L4: 46204 | M4: 46204 | N4: 46204 | O4: 46204 | P4: 46204 | Q4: 46235 | R4: 46235 | S4: 46235 | T4: 46235 | U4: 46235 | V4: 46266 | W4: 46266 | X4: 46266 | Y4: 46266 | Z4: 46266 | AA4: 46296 | AB4: 46296 | AC4: 46296 | AD4: 46296 | AE4: 46296 | AF4: 46327 | AG4: 46327 | AH4: 46327 | AI4: 46327 | AJ4: 46327 | AK4: 46357 | AL4: 46357 | AM4: 46357 | AN4: 46357 | AO4: 46357
B5: Inventory | C5: Non Inventory | D5: Services | E5: Patty Cash | F5: Month Total | G5: Inventory | H5: Non Inventory | I5: Services | J5: Patty Csh | K5: Month Total | L5: Inventory | M5: Non Inventory | N5: Services | O5: Patty Cash | P5: Month Total | Q5: Inventory | R5: Non Inventory | S5: Services | T5: Patty Cash | U5: Month Total | V5: Inventory | W5: Non Inventory | X5: Services | Y5: Patty Cash | Z5: Month Total | AA5: Inventory | AB5: Non Inventory | AC5: Services | AD5: Patty Cash | AE5: Month Total | AF5: Inventory | AG5: Non Inventory | AH5: Services | AI5: Patty Cash | AJ5: Month Total | AK5: Inventory | AL5: Non Inventory | AM5: Services | AN5: Patty Cash | AO5: Month Total
A6: Ishida No: 01 | B6: =IFERROR(SUMIFS('Daily Issuance'!$O:$O,'Daily Issuance'!$I:$I,$A6,'Daily Issuance'!$E:$E,"Inventory",'Daily Issuance'!$B:$B,">="&DATE(2026,5,1),'Daily Issuance'!$B:$B,"<"&DATE(2026,6,1)),0) -> 167000 | C6: =IFERROR(SUMIFS('Daily Issuance'!$O:$O,'Daily Issuance'!$I:$I,$A6,'Daily Issuance'!$E:$E,"Non Inventory",'Daily Issuance'!$B:$B,">="&DATE(2026,5,1),'Daily Issuance'!$B:$B,"<"&DATE(2026,6,1)),0) -> 672 | D6: =IFERROR(SUMIFS('Daily Issuance'!$O:$O,'Daily Issuance'!$I:$I,$A6,'Daily Issuance'!$E:$E,"Services",'Daily Issuance'!$B:$B,">="&DATE(2026,5,1),'Daily Issuance'!$B:$B,"<"&DATE(2026,6,1)),0) -> 0 | E6: =IFERROR(SUMIFS('Daily Issuance'!$O:$O,'Daily Issuance'!$I:$I,$A6,'Daily Issuance'!$E:$E,"Patty Cash",'Daily Issuance'!$B:$B,">="&DATE(2026,5,1),'Daily Issuance'!$B:$B,"<"&DATE(2026,6,1)),0) -> 0 | F6: =SUM(B6:E6) -> 167672 | G6: =IFERROR(SUMIFS('Daily Issuance'!$O$4:$O$991,'Daily Issuance'!$I$4:$I$991,$A6,'Daily Issuance'!$E$4:$E$991,"Inventory",'Daily Issuance'!$B$4:$B$991,">="&DATE(2026,6,1),'Daily Issuance'!$B$4:$B$991,"<"&DATE(2026,7,1)),0) -> 16450 | H6: =IFERROR(SUMIFS('Daily Issuance'!$O$4:$O$991,'Daily Issuance'!$I$4:$I$991,$A6,'Daily Issuance'!$E$4:$E$991,"Non Inventory",'Daily Issuance'!$B$4:$B$991,">="&DATE(2026,6,1),'Daily Issuance'!$B$4:$B$991,"<"&DATE(2026,7,1)),0) -> 512 | I6: =IFERROR(SUMIFS('Daily Issuance'!$O$4:$O$991,'Daily Issuance'!$I$4:$I$991,$A6,'Daily Issuance'!$E$4:$E$991,"Services",'Daily Issuance'!$B$4:$B$991,">="&DATE(2026,6,1),'Daily Issuance'!$B$4:$B$991,"<"&DATE(2026,7,1)),0) -> 0 | J6: =IFERROR(SUMIFS('Daily Issuance'!$O:$O,'Daily Issuance'!$I:$I,$A6,'Daily Issuance'!$E:$E,"Patty Cash",'Daily Issuance'!$B:$B,">="&DATE(2026,6,1),'Daily Issuance'!$B:$B,"<"&DATE(2026,7,1)),0) -> 0 | K6: =SUM(G6:J6) -> 16962 | L6: =IFERROR(SUMIFS('Daily Issuance'!$O$4:$O$991,'Daily Issuance'!$I$4:$I$991,$A6,'Daily Issuance'!$E$4:$E$991,"Inventory",'Daily Issuance'!$B$4:$B$991,">="&DATE(2026,7,1),'Daily Issuance'!$B$4:$B$991,"<"&DATE(2026,8,1)),0) -> 0 | M6: =IFERROR(SUMIFS('Daily Issuance'!$O$4:$O$991,'Daily Issuance'!$I$4:$I$991,$A6,'Daily Issuance'!$E$4:$E$991,"Non Inventory",'Daily Issuance'!$B$4:$B$991,">="&DATE(2026,7,1),'Daily Issuance'!$B$4:$B$991,"<"&DATE(2026,8,1)),0) -> 0 | N6: =IFERROR(SUMIFS('Daily Issuance'!$O$4:$O$991,'Daily Issuance'!$I$4:$I$991,$A6,'Daily Issuance'!$E$4:$E$991,"Services",'Daily Issuance'!$B$4:$B$991,">="&DATE(2026,7,1),'Daily Issuance'!$B$4:$B$991,"<"&DATE(2026,8,1)),0) -> 0 | O6: =IFERROR(SUMIFS('Daily Issuance'!$O:$O,'Daily Issuance'!$I:$I,$A6,'Daily Issuance'!$E:$E,"Patty Cash",'Daily Issuance'!$B:$B,">="&DATE(2026,7,1),'Daily Issuance'!$B:$B,"<"&DATE(2026,8,1)),0) -> 0 | P6: =SUM(L6:O6) -> 0 | Q6: =IFERROR(SUMIFS('Daily Issuance'!$O$4:$O$991,'Daily Issuance'!$I$4:$I$991,$A6,'Daily Issuance'!$E$4:$E$991,"Inventory",'Daily Issuance'!$B$4:$B$991,">="&DATE(2026,8,1),'Daily Issuance'!$B$4:$B$991,"<"&DATE(2026,9,1)),0) -> 0 | R6: =IFERROR(SUMIFS('Daily Issuance'!$O$4:$O$991,'Daily Issuance'!$I$4:$I$991,$A6,'Daily Issuance'!$E$4:$E$991,"Non Inventory",'Daily Issuance'!$B$4:$B$991,">="&DATE(2026,8,1),'Daily Issuance'!$B$4:$B$991,"<"&DATE(2026,9,1)),0) -> 0 | S6: =IFERROR(SUMIFS('Daily Issuance'!$O$4:$O$991,'Daily Issuance'!$I$4:$I$991,$A6,'Daily Issuance'!$E$4:$E$991,"Services",'Daily Issuance'!$B$4:$B$991,">="&DATE(2026,8,1),'Daily Issuance'!$B$4:$B$991,"<"&DATE(2026,9,1)),0) -> 0 | T6: =IFERROR(SUMIFS('Daily Issuance'!$O:$O,'Daily Issuance'!$I:$I,$A6,'Daily Issuance'!$E:$E,"Patty Cash",'Daily Issuance'!$B:$B,">="&DATE(2026,8,1),'Daily Issuance'!$B:$B,"<"&DATE(2026,9,1)),0) -> 0 | U6: =SUM(Q6:T6) -> 0 | V6: =IFERROR(SUMIFS('Daily Issuance'!$O$4:$O$991,'Daily Issuance'!$I$4:$I$991,$A6,'Daily Issuance'!$E$4:$E$991,"Inventory",'Daily Issuance'!$B$4:$B$991,">="&DATE(2026,9,1),'Daily Issuance'!$B$4:$B$991,"<"&DATE(2026,10,1)),0) -> 0 | W6: =IFERROR(SUMIFS('Daily Issuance'!$O$4:$O$991,'Daily Issuance'!$I$4:$I$991,$A6,'Daily Issuance'!$E$4:$E$991,"Non Inventory",'Daily Issuance'!$B$4:$B$991,">="&DATE(2026,9,1),'Daily Issuance'!$B$4:$B$991,"<"&DATE(2026,10,1)),0) -> 0 | X6: =IFERROR(SUMIFS('Daily Issuance'!$O$4:$O$991,'Daily Issuance'!$I$4:$I$991,$A6,'Daily Issuance'!$E$4:$E$991,"Services",'Daily Issuance'!$B$4:$B$991,">="&DATE(2026,9,1),'Daily Issuance'!$B$4:$B$991,"<"&DATE(2026,10,1)),0) -> 0 | Y6: =IFERROR(SUMIFS('Daily Issuance'!$O:$O,'Daily Issuance'!$I:$I,$A6,'Daily Issuance'!$E:$E,"Patty Cash",'Daily Issuance'!$B:$B,">="&DATE(2026,9,1),'Daily Issuance'!$B:$B,"<"&DATE(2026,10,1)),0) -> 0 | Z6: =SUM(V6:Y6) -> 0 | AA6: =IFERROR(SUMIFS('Daily Issuance'!$O$4:$O$991,'Daily Issuance'!$I$4:$I$991,$A6,'Daily Issuance'!$E$4:$E$991,"Inventory",'Daily Issuance'!$B$4:$B$991,">="&DATE(2026,10,1),'Daily Issuance'!$B$4:$B$991,"<"&DATE(2026,11,1)),0) -> 0 | AB6: =IFERROR(SUMIFS('Daily Issuance'!$O$4:$O$991,'Daily Issuance'!$I$4:$I$991,$A6,'Daily Issuance'!$E$4:$E$991,"Non Inventory",'Daily Issuance'!$B$4:$B$991,">="&DATE(2026,10,1),'Daily Issuance'!$B$4:$B$991,"<"&DATE(2026,11,1)),0) -> 0 | AC6: =IFERROR(SUMIFS('Daily Issuance'!$O$4:$O$991,'Daily Issuance'!$I$4:$I$991,$A6,'Daily Issuance'!$E$4:$E$991,"Services",'Daily Issuance'!$B$4:$B$991,">="&DATE(2026,10,1),'Daily Issuance'!$B$4:$B$991,"<"&DATE(2026,11,1)),0) -> 0 | AD6: =IFERROR(SUMIFS('Daily Issuance'!$O:$O,'Daily Issuance'!$I:$I,$A6,'Daily Issuance'!$E:$E,"Patty Cash",'Daily Issuance'!$B:$B,">="&DATE(2026,10,1),'Daily Issuance'!$B:$B,"<"&DATE(2026,11,1)),0) -> 0 | AE6: =SUM(AA6:AD6) -> 0 | AF6: =IFERROR(SUMIFS('Daily Issuance'!$O$4:$O$991,'Daily Issuance'!$I$4:$I$991,$A6,'Daily Issuance'!$E$4:$E$991,"Inventory",'Daily Issuance'!$B$4:$B$991,">="&DATE(2026,11,1),'Daily Issuance'!$B$4:$B$991,"<"&DATE(2026,12,1)),0) -> 0 | AG6: =IFERROR(SUMIFS('Daily Issuance'!$O$4:$O$991,'Daily Issuance'!$I$4:$I$991,$A6,'Daily Issuance'!$E$4:$E$991,"Non Inventory",'Daily Issuance'!$B$4:$B$991,">="&DATE(2026,11,1),'Daily Issuance'!$B$4:$B$991,"<"&DATE(2026,12,1)),0) -> 0 | AH6: =IFERROR(SUMIFS('Daily Issuance'!$O$4:$O$991,'Daily Issuance'!$I$4:$I$991,$A6,'Daily Issuance'!$E$4:$E$991,"Services",'Daily Issuance'!$B$4:$B$991,">="&DATE(2026,11,1),'Daily Issuance'!$B$4:$B$991,"<"&DATE(2026,12,1)),0) -> 0 | AI6: =IFERROR(SUMIFS('Daily Issuance'!$O:$O,'Daily Issuance'!$I:$I,$A6,'Daily Issuance'!$E:$E,"Patty Cash",'Daily Issuance'!$B:$B,">="&DATE(2026,11,1),'Daily Issuance'!$B:$B,"<"&DATE(2026,12,1)),0) -> 0 | AJ6: =SUM(AF6:AI6) -> 0 | AK6: =IFERROR(SUMIFS('Daily Issuance'!$O$4:$O$991,'Daily Issuance'!$I$4:$I$991,$A6,'Daily Issuance'!$E$4:$E$991,"Inventory",'Daily Issuance'!$B$4:$B$991,">="&DATE(2026,12,1),'Daily Issuance'!$B$4:$B$991,"<"&DATE(2027,1,1)),0) -> 0 | AL6: =IFERROR(SUMIFS('Daily Issuance'!$O$4:$O$991,'Daily Issuance'!$I$4:$I$991,$A6,'Daily Issuance'!$E$4:$E$991,"Non Inventory",'Daily Issuance'!$B$4:$B$991,">="&DATE(2026,12,1),'Daily Issuance'!$B$4:$B$991,"<"&DATE(2027,1,1)),0) -> 0 | AM6: =IFERROR(SUMIFS('Daily Issuance'!$O$4:$O$991,'Daily Issuance'!$I$4:$I$991,$A6,'Daily Issuance'!$E$4:$E$991,"Services",'Daily Issuance'!$B$4:$B$991,">="&DATE(2026,12,1),'Daily Issuance'!$B$4:$B$991,"<"&DATE(2027,1,1)),0) -> 0 | AN6: =IFERROR(SUMIFS('Daily Issuance'!$O:$O,'Daily Issuance'!$I:$I,$A6,'Daily Issuance'!$E:$E,"Patty Cash",'Daily Issuance'!$B:$B,">="&DATE(2026,12,1),'Daily Issuance'!$B:$B,"<"&DATE(2027,1,1)),0) -> 0 | AO6: =SUM(AK6:AN6) -> 0 | AP6: =SUM(F6,K6,P6,U6,Z6,AE6,AJ6,AO6) -> 184634
A7: Ishida No: 02 | B7: =IFERROR(SUMIFS('Daily Issuance'!$O:$O,'Daily Issuance'!$I:$I,$A7,'Daily Issuance'!$E:$E,"Inventory",'Daily Issuance'!$B:$B,">="&DATE(2026,5,1),'Daily Issuance'!$B:$B,"<"&DATE(2026,6,1)),0) -> 8550 | C7: =IFERROR(SUMIFS('Daily Issuance'!$O:$O,'Daily Issuance'!$I:$I,$A7,'Daily Issuance'!$E:$E,"Non Inventory",'Daily Issuance'!$B:$B,">="&DATE(2026,5,1),'Daily Issuance'!$B:$B,"<"&DATE(2026,6,1)),0) -> 1456 | D7: =IFERROR(SUMIFS('Daily Issuance'!$O:$O,'Daily Issuance'!$I:$I,$A7,'Daily Issuance'!$E:$E,"Services",'Daily Issuance'!$B:$B,">="&DATE(2026,5,1),'Daily Issuance'!$B:$B,"<"&DATE(2026,6,1)),0) -> 0 | E7: =IFERROR(SUMIFS('Daily Issuance'!$O:$O,'Daily Issuance'!$I:$I,$A7,'Daily Issuance'!$E:$E,"Patty Cash",'Daily Issuance'!$B:$B,">="&DATE(2026,5,1),'Daily Issuance'!$B:$B,"<"&DATE(2026,6,1)),0) -> 0 | F7: =SUM(B7:E7) -> 10006 | G7: =IFERROR(SUMIFS('Daily Issuance'!$O$4:$O$991,'Daily Issuance'!$I$4:$I$991,$A7,'Daily Issuance'!$E$4:$E$991,"Inventory",'Daily Issuance'!$B$4:$B$991,">="&DATE(2026,6,1),'Daily Issuance'!$B$4:$B$991,"<"&DATE(2026,7,1)),0) -> 1007000 | H7: =IFERROR(SUMIFS('Daily Issuance'!$O$4:$O$991,'Daily Issuance'!$I$4:$I$991,$A7,'Daily Issuance'!$E$4:$E$991,"Non Inventory",'Daily Issuance'!$B$4:$B$991,">="&DATE(2026,6,1),'Daily Issuance'!$B$4:$B$991,"<"&DATE(2026,7,1)),0) -> 768 | I7: =IFERROR(SUMIFS('Daily Issuance'!$O$4:$O$991,'Daily Issuance'!$I$4:$I$991,$A7,'Daily Issuance'!$E$4:$E$991,"Services",'Daily Issuance'!$B$4:$B$991,">="&DATE(2026,6,1),'Daily Issuance'!$B$4:$B$991,"<"&DATE(2026,7,1)),0) -> 0 | J7: =IFERROR(SUMIFS('Daily Issuance'!$O:$O,'Daily Issuance'!$I:$I,$A7,'Daily Issuance'!$E:$E,"Patty Cash",'Daily Issuance'!$B:$B,">="&DATE(2026,6,1),'Daily Issuance'!$B:$B,"<"&DATE(2026,7,1)),0) -> 0 | K7: =SUM(G7:J7) -> 1007768 | L7: =IFERROR(SUMIFS('Daily Issuance'!$O$4:$O$991,'Daily Issuance'!$I$4:$I$991,$A7,'Daily Issuance'!$E$4:$E$991,"Inventory",'Daily Issuance'!$B$4:$B$991,">="&DATE(2026,7,1),'Daily Issuance'!$B$4:$B$991,"<"&DATE(2026,8,1)),0) -> 0 | M7: =IFERROR(SUMIFS('Daily Issuance'!$O$4:$O$991,'Daily Issuance'!$I$4:$I$991,$A7,'Daily Issuance'!$E$4:$E$991,"Non Inventory",'Daily Issuance'!$B$4:$B$991,">="&DATE(2026,7,1),'Daily Issuance'!$B$4:$B$991,"<"&DATE(2026,8,1)),0) -> 0 | N7: =IFERROR(SUMIFS('Daily Issuance'!$O$4:$O$991,'Daily Issuance'!$I$4:$I$991,$A7,'Daily Issuance'!$E$4:$E$991,"Services",'Daily Issuance'!$B$4:$B$991,">="&DATE(2026,7,1),'Daily Issuance'!$B$4:$B$991,"<"&DATE(2026,8,1)),0) -> 0 | O7: =IFERROR(SUMIFS('Daily Issuance'!$O:$O,'Daily Issuance'!$I:$I,$A7,'Daily Issuance'!$E:$E,"Patty Cash",'Daily Issuance'!$B:$B,">="&DATE(2026,7,1),'Daily Issuance'!$B:$B,"<"&DATE(2026,8,1)),0) -> 0 | P7: =SUM(L7:O7) -> 0 | Q7: =IFERROR(SUMIFS('Daily Issuance'!$O$4:$O$991,'Daily Issuance'!$I$4:$I$991,$A7,'Daily Issuance'!$E$4:$E$991,"Inventory",'Daily Issuance'!$B$4:$B$991,">="&DATE(2026,8,1),'Daily Issuance'!$B$4:$B$991,"<"&DATE(2026,9,1)),0) -> 0 | R7: =IFERROR(SUMIFS('Daily Issuance'!$O$4:$O$991,'Daily Issuance'!$I$4:$I$991,$A7,'Daily Issuance'!$E$4:$E$991,"Non Inventory",'Daily Issuance'!$B$4:$B$991,">="&DATE(2026,8,1),'Daily Issuance'!$B$4:$B$991,"<"&DATE(2026,9,1)),0) -> 0 | S7: =IFERROR(SUMIFS('Daily Issuance'!$O$4:$O$991,'Daily Issuance'!$I$4:$I$991,$A7,'Daily Issuance'!$E$4:$E$991,"Services",'Daily Issuance'!$B$4:$B$991,">="&DATE(2026,8,1),'Daily Issuance'!$B$4:$B$991,"<"&DATE(2026,9,1)),0) -> 0 | T7: =IFERROR(SUMIFS('Daily Issuance'!$O:$O,'Daily Issuance'!$I:$I,$A7,'Daily Issuance'!$E:$E,"Patty Cash",'Daily Issuance'!$B:$B,">="&DATE(2026,8,1),'Daily Issuance'!$B:$B,"<"&DATE(2026,9,1)),0) -> 0 | U7: =SUM(Q7:T7) -> 0 | V7: =IFERROR(SUMIFS('Daily Issuance'!$O$4:$O$991,'Daily Issuance'!$I$4:$I$991,$A7,'Daily Issuance'!$E$4:$E$991,"Inventory",'Daily Issuance'!$B$4:$B$991,">="&DATE(2026,9,1),'Daily Issuance'!$B$4:$B$991,"<"&DATE(2026,10,1)),0) -> 0 | W7: =IFERROR(SUMIFS('Daily Issuance'!$O$4:$O$991,'Daily Issuance'!$I$4:$I$991,$A7,'Daily Issuance'!$E$4:$E$991,"Non Inventory",'Daily Issuance'!$B$4:$B$991,">="&DATE(2026,9,1),'Daily Issuance'!$B$4:$B$991,"<"&DATE(2026,10,1)),0) -> 0 | X7: =IFERROR(SUMIFS('Daily Issuance'!$O$4:$O$991,'Daily Issuance'!$I$4:$I$991,$A7,'Daily Issuance'!$E$4:$E$991,"Services",'Daily Issuance'!$B$4:$B$991,">="&DATE(2026,9,1),'Daily Issuance'!$B$4:$B$991,"<"&DATE(2026,10,1)),0) -> 0 | Y7: =IFERROR(SUMIFS('Daily Issuance'!$O:$O,'Daily Issuance'!$I:$I,$A7,'Daily Issuance'!$E:$E,"Patty Cash",'Daily Issuance'!$B:$B,">="&DATE(2026,9,1),'Daily Issuance'!$B:$B,"<"&DATE(2026,10,1)),0) -> 0 | Z7: =SUM(V7:Y7) -> 0 | AA7: =IFERROR(SUMIFS('Daily Issuance'!$O$4:$O$991,'Daily Issuance'!$I$4:$I$991,$A7,'Daily Issuance'!$E$4:$E$991,"Inventory",'Daily Issuance'!$B$4:$B$991,">="&DATE(2026,10,1),'Daily Issuance'!$B$4:$B$991,"<"&DATE(2026,11,1)),0) -> 0 | AB7: =IFERROR(SUMIFS('Daily Issuance'!$O$4:$O$991,'Daily Issuance'!$I$4:$I$991,$A7,'Daily Issuance'!$E$4:$E$991,"Non Inventory",'Daily Issuance'!$B$4:$B$991,">="&DATE(2026,10,1),'Daily Issuance'!$B$4:$B$991,"<"&DATE(2026,11,1)),0) -> 0 | AC7: =IFERROR(SUMIFS('Daily Issuance'!$O$4:$O$991,'Daily Issuance'!$I$4:$I$991,$A7,'Daily Issuance'!$E$4:$E$991,"Services",'Daily Issuance'!$B$4:$B$991,">="&DATE(2026,10,1),'Daily Issuance'!$B$4:$B$991,"<"&DATE(2026,11,1)),0) -> 0 | AD7: =IFERROR(SUMIFS('Daily Issuance'!$O:$O,'Daily Issuance'!$I:$I,$A7,'Daily Issuance'!$E:$E,"Patty Cash",'Daily Issuance'!$B:$B,">="&DATE(2026,10,1),'Daily Issuance'!$B:$B,"<"&DATE(2026,11,1)),0) -> 0 | AE7: =SUM(AA7:AD7) -> 0 | AF7: =IFERROR(SUMIFS('Daily Issuance'!$O$4:$O$991,'Daily Issuance'!$I$4:$I$991,$A7,'Daily Issuance'!$E$4:$E$991,"Inventory",'Daily Issuance'!$B$4:$B$991,">="&DATE(2026,11,1),'Daily Issuance'!$B$4:$B$991,"<"&DATE(2026,12,1)),0) -> 0 | AG7: =IFERROR(SUMIFS('Daily Issuance'!$O$4:$O$991,'Daily Issuance'!$I$4:$I$991,$A7,'Daily Issuance'!$E$4:$E$991,"Non Inventory",'Daily Issuance'!$B$4:$B$991,">="&DATE(2026,11,1),'Daily Issuance'!$B$4:$B$991,"<"&DATE(2026,12,1)),0) -> 0 | AH7: =IFERROR(SUMIFS('Daily Issuance'!$O$4:$O$991,'Daily Issuance'!$I$4:$I$991,$A7,'Daily Issuance'!$E$4:$E$991,"Services",'Daily Issuance'!$B$4:$B$991,">="&DATE(2026,11,1),'Daily Issuance'!$B$4:$B$991,"<"&DATE(2026,12,1)),0) -> 0 | AI7: =IFERROR(SUMIFS('Daily Issuance'!$O:$O,'Daily Issuance'!$I:$I,$A7,'Daily Issuance'!$E:$E,"Patty Cash",'Daily Issuance'!$B:$B,">="&DATE(2026,11,1),'Daily Issuance'!$B:$B,"<"&DATE(2026,12,1)),0) -> 0 | AJ7: =SUM(AF7:AI7) -> 0 | AK7: =IFERROR(SUMIFS('Daily Issuance'!$O$4:$O$991,'Daily Issuance'!$I$4:$I$991,$A7,'Daily Issuance'!$E$4:$E$991,"Inventory",'Daily Issuance'!$B$4:$B$991,">="&DATE(2026,12,1),'Daily Issuance'!$B$4:$B$991,"<"&DATE(2027,1,1)),0) -> 0 | AL7: =IFERROR(SUMIFS('Daily Issuance'!$O$4:$O$991,'Daily Issuance'!$I$4:$I$991,$A7,'Daily Issuance'!$E$4:$E$991,"Non Inventory",'Daily Issuance'!$B$4:$B$991,">="&DATE(2026,12,1),'Daily Issuance'!$B$4:$B$991,"<"&DATE(2027,1,1)),0) -> 0 | AM7: =IFERROR(SUMIFS('Daily Issuance'!$O$4:$O$991,'Daily Issuance'!$I$4:$I$991,$A7,'Daily Issuance'!$E$4:$E$991,"Services",'Daily Issuance'!$B$4:$B$991,">="&DATE(2026,12,1),'Daily Issuance'!$B$4:$B$991,"<"&DATE(2027,1,1)),0) -> 0 | AN7: =IFERROR(SUMIFS('Daily Issuance'!$O:$O,'Daily Issuance'!$I:$I,$A7,'Daily Issuance'!$E:$E,"Patty Cash",'Daily Issuance'!$B:$B,">="&DATE(2026,12,1),'Daily Issuance'!$B:$B,"<"&DATE(2027,1,1)),0) -> 0 | AO7: =SUM(AK7:AN7) -> 0 | AP7: =SUM(F7,K7,P7,U7,Z7,AE7,AJ7,AO7) -> 1017774
A8: Ishida No: 03 | B8: =IFERROR(SUMIFS('Daily Issuance'!$O:$O,'Daily Issuance'!$I:$I,$A8,'Daily Issuance'!$E:$E,"Inventory",'Daily Issuance'!$B:$B,">="&DATE(2026,5,1),'Daily Issuance'!$B:$B,"<"&DATE(2026,6,1)),0) -> 16852 | C8: =IFERROR(SUMIFS('Daily Issuance'!$O:$O,'Daily Issuance'!$I:$I,$A8,'Daily Issuance'!$E:$E,"Non Inventory",'Daily Issuance'!$B:$B,">="&DATE(2026,5,1),'Daily Issuance'!$B:$B,"<"&DATE(2026,6,1)),0) -> 6000 | D8: =IFERROR(SUMIFS('Daily Issuance'!$O:$O,'Daily Issuance'!$I:$I,$A8,'Daily Issuance'!$E:$E,"Services",'Daily Issuance'!$B:$B,">="&DATE(2026,5,1),'Daily Issuance'!$B:$B,"<"&DATE(2026,6,1)),0) -> 0 | E8: =IFERROR(SUMIFS('Daily Issuance'!$O:$O,'Daily Issuance'!$I:$I,$A8,'Daily Issuance'!$E:$E,"Patty Cash",'Daily Issuance'!$B:$B,">="&DATE(2026,5,1),'Daily Issuance'!$B:$B,"<"&DATE(2026,6,1)),0) -> 0 | F8: =SUM(B8:E8) -> 22852 | G8: =IFERROR(SUMIFS('Daily Issuance'!$O$4:$O$991,'Daily Issuance'!$I$4:$I$991,$A8,'Daily Issuance'!$E$4:$E$991,"Inventory",'Daily Issuance'!$B$4:$B$991,">="&DATE(2026,6,1),'Daily Issuance'!$B$4:$B$991,"<"&DATE(2026,7,1)),0) -> 1650 | H8: =IFERROR(SUMIFS('Daily Issuance'!$O$4:$O$991,'Daily Issuance'!$I$4:$I$991,$A8,'Daily Issuance'!$E$4:$E$991,"Non Inventory",'Daily Issuance'!$B$4:$B$991,">="&DATE(2026,6,1),'Daily Issuance'!$B$4:$B$991,"<"&DATE(2026,7,1)),0) -> 512 | I8: =IFERROR(SUMIFS('Daily Issuance'!$O$4:$O$991,'Daily Issuance'!$I$4:$I$991,$A8,'Daily Issuance'!$E$4:$E$991,"Services",'Daily Issuance'!$B$4:$B$991,">="&DATE(2026,6,1),'Daily Issuance'!$B$4:$B$991,"<"&DATE(2026,7,1)),0) -> 0 | J8: =IFERROR(SUMIFS('Daily Issuance'!$O:$O,'Daily Issuance'!$I:$I,$A8,'Daily Issuance'!$E:$E,"Patty Cash",'Daily Issuance'!$B:$B,">="&DATE(2026,6,1),'Daily Issuance'!$B:$B,"<"&DATE(2026,7,1)),0) -> 0 | K8: =SUM(G8:J8) -> 2162 | L8: =IFERROR(SUMIFS('Daily Issuance'!$O$4:$O$991,'Daily Issuance'!$I$4:$I$991,$A8,'Daily Issuance'!$E$4:$E$991,"Inventory",'Daily Issuance'!$B$4:$B$991,">="&DATE(2026,7,1),'Daily Issuance'!$B$4:$B$991,"<"&DATE(2026,8,1)),0) -> 0 | M8: =IFERROR(SUMIFS('Daily Issuance'!$O$4:$O$991,'Daily Issuance'!$I$4:$I$991,$A8,'Daily Issuance'!$E$4:$E$991,"Non Inventory",'Daily Issuance'!$B$4:$B$991,">="&DATE(2026,7,1),'Daily Issuance'!$B$4:$B$991,"<"&DATE(2026,8,1)),0) -> 0 | N8: =IFERROR(SUMIFS('Daily Issuance'!$O$4:$O$991,'Daily Issuance'!$I$4:$I$991,$A8,'Daily Issuance'!$E$4:$E$991,"Services",'Daily Issuance'!$B$4:$B$991,">="&DATE(2026,7,1),'Daily Issuance'!$B$4:$B$991,"<"&DATE(2026,8,1)),0) -> 0 | O8: =IFERROR(SUMIFS('Daily Issuance'!$O:$O,'Daily Issuance'!$I:$I,$A8,'Daily Issuance'!$E:$E,"Patty Cash",'Daily Issuance'!$B:$B,">="&DATE(2026,7,1),'Daily Issuance'!$B:$B,"<"&DATE(2026,8,1)),0) -> 0 | P8: =SUM(L8:O8) -> 0 | Q8: =IFERROR(SUMIFS('Daily Issuance'!$O$4:$O$991,'Daily Issuance'!$I$4:$I$991,$A8,'Daily Issuance'!$E$4:$E$991,"Inventory",'Daily Issuance'!$B$4:$B$991,">="&DATE(2026,8,1),'Daily Issuance'!$B$4:$B$991,"<"&DATE(2026,9,1)),0) -> 0 | R8: =IFERROR(SUMIFS('Daily Issuance'!$O$4:$O$991,'Daily Issuance'!$I$4:$I$991,$A8,'Daily Issuance'!$E$4:$E$991,"Non Inventory",'Daily Issuance'!$B$4:$B$991,">="&DATE(2026,8,1),'Daily Issuance'!$B$4:$B$991,"<"&DATE(2026,9,1)),0) -> 0 | S8: =IFERROR(SUMIFS('Daily Issuance'!$O$4:$O$991,'Daily Issuance'!$I$4:$I$991,$A8,'Daily Issuance'!$E$4:$E$991,"Services",'Daily Issuance'!$B$4:$B$991,">="&DATE(2026,8,1),'Daily Issuance'!$B$4:$B$991,"<"&DATE(2026,9,1)),0) -> 0 | T8: =IFERROR(SUMIFS('Daily Issuance'!$O:$O,'Daily Issuance'!$I:$I,$A8,'Daily Issuance'!$E:$E,"Patty Cash",'Daily Issuance'!$B:$B,">="&DATE(2026,8,1),'Daily Issuance'!$B:$B,"<"&DATE(2026,9,1)),0) -> 0 | U8: =SUM(Q8:T8) -> 0 | V8: =IFERROR(SUMIFS('Daily Issuance'!$O$4:$O$991,'Daily Issuance'!$I$4:$I$991,$A8,'Daily Issuance'!$E$4:$E$991,"Inventory",'Daily Issuance'!$B$4:$B$991,">="&DATE(2026,9,1),'Daily Issuance'!$B$4:$B$991,"<"&DATE(2026,10,1)),0) -> 0 | W8: =IFERROR(SUMIFS('Daily Issuance'!$O$4:$O$991,'Daily Issuance'!$I$4:$I$991,$A8,'Daily Issuance'!$E$4:$E$991,"Non Inventory",'Daily Issuance'!$B$4:$B$991,">="&DATE(2026,9,1),'Daily Issuance'!$B$4:$B$991,"<"&DATE(2026,10,1)),0) -> 0 | X8: =IFERROR(SUMIFS('Daily Issuance'!$O$4:$O$991,'Daily Issuance'!$I$4:$I$991,$A8,'Daily Issuance'!$E$4:$E$991,"Services",'Daily Issuance'!$B$4:$B$991,">="&DATE(2026,9,1),'Daily Issuance'!$B$4:$B$991,"<"&DATE(2026,10,1)),0) -> 0 | Y8: =IFERROR(SUMIFS('Daily Issuance'!$O:$O,'Daily Issuance'!$I:$I,$A8,'Daily Issuance'!$E:$E,"Patty Cash",'Daily Issuance'!$B:$B,">="&DATE(2026,9,1),'Daily Issuance'!$B:$B,"<"&DATE(2026,10,1)),0) -> 0 | Z8: =SUM(V8:Y8) -> 0 | AA8: =IFERROR(SUMIFS('Daily Issuance'!$O$4:$O$991,'Daily Issuance'!$I$4:$I$991,$A8,'Daily Issuance'!$E$4:$E$991,"Inventory",'Daily Issuance'!$B$4:$B$991,">="&DATE(2026,10,1),'Daily Issuance'!$B$4:$B$991,"<"&DATE(2026,11,1)),0) -> 0 | AB8: =IFERROR(SUMIFS('Daily Issuance'!$O$4:$O$991,'Daily Issuance'!$I$4:$I$991,$A8,'Daily Issuance'!$E$4:$E$991,"Non Inventory",'Daily Issuance'!$B$4:$B$991,">="&DATE(2026,10,1),'Daily Issuance'!$B$4:$B$991,"<"&DATE(2026,11,1)),0) -> 0 | AC8: =IFERROR(SUMIFS('Daily Issuance'!$O$4:$O$991,'Daily Issuance'!$I$4:$I$991,$A8,'Daily Issuance'!$E$4:$E$991,"Services",'Daily Issuance'!$B$4:$B$991,">="&DATE(2026,10,1),'Daily Issuance'!$B$4:$B$991,"<"&DATE(2026,11,1)),0) -> 0 | AD8: =IFERROR(SUMIFS('Daily Issuance'!$O:$O,'Daily Issuance'!$I:$I,$A8,'Daily Issuance'!$E:$E,"Patty Cash",'Daily Issuance'!$B:$B,">="&DATE(2026,10,1),'Daily Issuance'!$B:$B,"<"&DATE(2026,11,1)),0) -> 0 | AE8: =SUM(AA8:AD8) -> 0 | AF8: =IFERROR(SUMIFS('Daily Issuance'!$O$4:$O$991,'Daily Issuance'!$I$4:$I$991,$A8,'Daily Issuance'!$E$4:$E$991,"Inventory",'Daily Issuance'!$B$4:$B$991,">="&DATE(2026,11,1),'Daily Issuance'!$B$4:$B$991,"<"&DATE(2026,12,1)),0) -> 0 | AG8: =IFERROR(SUMIFS('Daily Issuance'!$O$4:$O$991,'Daily Issuance'!$I$4:$I$991,$A8,'Daily Issuance'!$E$4:$E$991,"Non Inventory",'Daily Issuance'!$B$4:$B$991,">="&DATE(2026,11,1),'Daily Issuance'!$B$4:$B$991,"<"&DATE(2026,12,1)),0) -> 0 | AH8: =IFERROR(SUMIFS('Daily Issuance'!$O$4:$O$991,'Daily Issuance'!$I$4:$I$991,$A8,'Daily Issuance'!$E$4:$E$991,"Services",'Daily Issuance'!$B$4:$B$991,">="&DATE(2026,11,1),'Daily Issuance'!$B$4:$B$991,"<"&DATE(2026,12,1)),0) -> 0 | AI8: =IFERROR(SUMIFS('Daily Issuance'!$O:$O,'Daily Issuance'!$I:$I,$A8,'Daily Issuance'!$E:$E,"Patty Cash",'Daily Issuance'!$B:$B,">="&DATE(2026,11,1),'Daily Issuance'!$B:$B,"<"&DATE(2026,12,1)),0) -> 0 | AJ8: =SUM(AF8:AI8) -> 0 | AK8: =IFERROR(SUMIFS('Daily Issuance'!$O$4:$O$991,'Daily Issuance'!$I$4:$I$991,$A8,'Daily Issuance'!$E$4:$E$991,"Inventory",'Daily Issuance'!$B$4:$B$991,">="&DATE(2026,12,1),'Daily Issuance'!$B$4:$B$991,"<"&DATE(2027,1,1)),0) -> 0 | AL8: =IFERROR(SUMIFS('Daily Issuance'!$O$4:$O$991,'Daily Issuance'!$I$4:$I$991,$A8,'Daily Issuance'!$E$4:$E$991,"Non Inventory",'Daily Issuance'!$B$4:$B$991,">="&DATE(2026,12,1),'Daily Issuance'!$B$4:$B$991,"<"&DATE(2027,1,1)),0) -> 0 | AM8: =IFERROR(SUMIFS('Daily Issuance'!$O$4:$O$991,'Daily Issuance'!$I$4:$I$991,$A8,'Daily Issuance'!$E$4:$E$991,"Services",'Daily Issuance'!$B$4:$B$991,">="&DATE(2026,12,1),'Daily Issuance'!$B$4:$B$991,"<"&DATE(2027,1,1)),0) -> 0 | AN8: =IFERROR(SUMIFS('Daily Issuance'!$O:$O,'Daily Issuance'!$I:$I,$A8,'Daily Issuance'!$E:$E,"Patty Cash",'Daily Issuance'!$B:$B,">="&DATE(2026,12,1),'Daily Issuance'!$B:$B,"<"&DATE(2027,1,1)),0) -> 0 | AO8: =SUM(AK8:AN8) -> 0 | AP8: =SUM(F8,K8,P8,U8,Z8,AE8,AJ8,AO8) -> 25014
